2019-11-04 21:59:15,166 ERROR: Exception on /edit/article [GET] [in /home/anonymous/sites/flask_mega/env/lib/python3.7/site-packages/flask/app.py:1891
Traceback (most recent call last):
  File "/home/anonymous/sites/flask_mega/env/lib/python3.7/site-packages/flask/app.py", line 2446, in wsgi_app
    response = self.full_dispatch_request()
  File "/home/anonymous/sites/flask_mega/env/lib/python3.7/site-packages/flask/app.py", line 1951, in full_dispatch_request
    rv = self.handle_user_exception(e)
  File "/home/anonymous/sites/flask_mega/env/lib/python3.7/site-packages/flask/app.py", line 1820, in handle_user_exception
    reraise(exc_type, exc_value, tb)
  File "/home/anonymous/sites/flask_mega/env/lib/python3.7/site-packages/flask/_compat.py", line 39, in reraise
    raise value
  File "/home/anonymous/sites/flask_mega/env/lib/python3.7/site-packages/flask/app.py", line 1949, in full_dispatch_request
    rv = self.dispatch_request()
  File "/home/anonymous/sites/flask_mega/env/lib/python3.7/site-packages/flask/app.py", line 1935, in dispatch_request
    return self.view_functions[rule.endpoint](**req.view_args)
  File "/home/anonymous/sites/flask_mega/env/lib/python3.7/site-packages/flask_login/utils.py", line 261, in decorated_view
    return func(*args, **kwargs)
  File "/home/anonymous/sites/flask_mega/app/routes.py", line 108, in edit_article
    return render_template("edit_article.html", title="Edit Article", form=form)
  File "/home/anonymous/sites/flask_mega/env/lib/python3.7/site-packages/flask/templating.py", line 140, in render_template
    ctx.app,
  File "/home/anonymous/sites/flask_mega/env/lib/python3.7/site-packages/flask/templating.py", line 120, in _render
    rv = template.render(context)
  File "/home/anonymous/sites/flask_mega/env/lib/python3.7/site-packages/jinja2/asyncsupport.py", line 76, in render
    return original_render(self, *args, **kwargs)
  File "/home/anonymous/sites/flask_mega/env/lib/python3.7/site-packages/jinja2/environment.py", line 1008, in render
    return self.environment.handle_exception(exc_info, True)
  File "/home/anonymous/sites/flask_mega/env/lib/python3.7/site-packages/jinja2/environment.py", line 780, in handle_exception
    reraise(exc_type, exc_value, tb)
  File "/home/anonymous/sites/flask_mega/env/lib/python3.7/site-packages/jinja2/_compat.py", line 37, in reraise
    raise value.with_traceback(tb)
  File "/home/anonymous/sites/flask_mega/app/templates/edit_article.html", line 1, in top-level template code
    {% extends "base.html" %}
  File "/home/anonymous/sites/flask_mega/env/lib/python3.7/site-packages/jinja2/environment.py", line 1005, in render
    return concat(self.root_render_func(self.new_context(vars)))
  File "/home/anonymous/sites/flask_mega/app/templates/edit_article.html", line 14, in root
    {% for error in form.username.errors %}
  File "/home/anonymous/sites/flask_mega/app/templates/base.html", line 58, in root
  File "/home/anonymous/sites/flask_mega/app/templates/edit_article.html", line 28, in block_content
    {{ form.tags() }}
  File "/home/anonymous/sites/flask_mega/env/lib/python3.7/site-packages/jinja2/environment.py", line 430, in getattr
    return getattr(obj, attribute)
jinja2.exceptions.UndefinedError: 'app.forms.EditArticleForm object' has no attribute 'username'
2019-11-04 21:59:16,653 ERROR: Exception on /edit/article [GET] [in /home/anonymous/sites/flask_mega/env/lib/python3.7/site-packages/flask/app.py:1891
Traceback (most recent call last):
  File "/home/anonymous/sites/flask_mega/env/lib/python3.7/site-packages/flask/app.py", line 2446, in wsgi_app
    response = self.full_dispatch_request()
  File "/home/anonymous/sites/flask_mega/env/lib/python3.7/site-packages/flask/app.py", line 1951, in full_dispatch_request
    rv = self.handle_user_exception(e)
  File "/home/anonymous/sites/flask_mega/env/lib/python3.7/site-packages/flask/app.py", line 1820, in handle_user_exception
    reraise(exc_type, exc_value, tb)
  File "/home/anonymous/sites/flask_mega/env/lib/python3.7/site-packages/flask/_compat.py", line 39, in reraise
    raise value
  File "/home/anonymous/sites/flask_mega/env/lib/python3.7/site-packages/flask/app.py", line 1949, in full_dispatch_request
    rv = self.dispatch_request()
  File "/home/anonymous/sites/flask_mega/env/lib/python3.7/site-packages/flask/app.py", line 1935, in dispatch_request
    return self.view_functions[rule.endpoint](**req.view_args)
  File "/home/anonymous/sites/flask_mega/env/lib/python3.7/site-packages/flask_login/utils.py", line 261, in decorated_view
    return func(*args, **kwargs)
  File "/home/anonymous/sites/flask_mega/app/routes.py", line 108, in edit_article
    return render_template("edit_article.html", title="Edit Article", form=form)
  File "/home/anonymous/sites/flask_mega/env/lib/python3.7/site-packages/flask/templating.py", line 140, in render_template
    ctx.app,
  File "/home/anonymous/sites/flask_mega/env/lib/python3.7/site-packages/flask/templating.py", line 120, in _render
    rv = template.render(context)
  File "/home/anonymous/sites/flask_mega/env/lib/python3.7/site-packages/jinja2/asyncsupport.py", line 76, in render
    return original_render(self, *args, **kwargs)
  File "/home/anonymous/sites/flask_mega/env/lib/python3.7/site-packages/jinja2/environment.py", line 1008, in render
    return self.environment.handle_exception(exc_info, True)
  File "/home/anonymous/sites/flask_mega/env/lib/python3.7/site-packages/jinja2/environment.py", line 780, in handle_exception
    reraise(exc_type, exc_value, tb)
  File "/home/anonymous/sites/flask_mega/env/lib/python3.7/site-packages/jinja2/_compat.py", line 37, in reraise
    raise value.with_traceback(tb)
  File "/home/anonymous/sites/flask_mega/app/templates/edit_article.html", line 1, in top-level template code
    {% extends "base.html" %}
  File "/home/anonymous/sites/flask_mega/env/lib/python3.7/site-packages/jinja2/environment.py", line 1005, in render
    return concat(self.root_render_func(self.new_context(vars)))
  File "/home/anonymous/sites/flask_mega/app/templates/edit_article.html", line 14, in root
    {% for error in form.username.errors %}
  File "/home/anonymous/sites/flask_mega/app/templates/base.html", line 58, in root
  File "/home/anonymous/sites/flask_mega/app/templates/edit_article.html", line 28, in block_content
    {{ form.tags() }}
  File "/home/anonymous/sites/flask_mega/env/lib/python3.7/site-packages/jinja2/environment.py", line 430, in getattr
    return getattr(obj, attribute)
jinja2.exceptions.UndefinedError: 'app.forms.EditArticleForm object' has no attribute 'username'
2019-11-04 22:02:22,805 INFO: Ochyro startup [in /home/anonymous/sites/flask_mega/app/__init__.py:30
2019-11-04 22:11:11,620 INFO: Ochyro startup [in /home/anonymous/sites/flask_mega/app/__init__.py:30
2019-11-04 22:14:50,563 INFO: Ochyro startup [in /home/anonymous/sites/flask_mega/app/__init__.py:30
2019-11-04 22:20:46,644 INFO: Ochyro startup [in /home/anonymous/sites/flask_mega/app/__init__.py:30
2019-11-04 22:21:00,361 INFO: Ochyro startup [in /home/anonymous/sites/flask_mega/app/__init__.py:30
2019-11-05 19:59:19,579 INFO: Ochyro startup [in /home/anonymous/sites/ochyro/core/__init__.py:30
2019-11-05 20:29:42,056 INFO: Ochyro startup [in /home/anonymous/sites/ochyro/core/__init__.py:30
2019-11-06 17:19:02,995 INFO: Ochyro startup [in /home/anonymous/sites/ochyro/core/__init__.py:30
2019-11-06 17:19:32,126 INFO: Ochyro startup [in /home/anonymous/sites/ochyro/core/__init__.py:30
2019-11-09 09:32:15,830 INFO: Ochyro startup [in /home/anonymous/sites/ochyro/core/__init__.py:30
