2019-11-01 22:28:37,551 INFO: Ochyro startup [in /home/anonymous/sites/flask_mega/app/__init__.py:30
2019-11-01 22:29:02,327 INFO: Ochyro startup [in /home/anonymous/sites/flask_mega/app/__init__.py:30
2019-11-02 17:39:23,564 INFO: Ochyro startup [in /home/anonymous/sites/flask_mega/app/__init__.py:30
2019-11-02 17:39:32,600 INFO: Ochyro startup [in /home/anonymous/sites/flask_mega/app/__init__.py:30
2019-11-02 23:18:33,768 INFO: Ochyro startup [in /home/anonymous/sites/flask_mega/app/__init__.py:30
2019-11-02 23:18:39,621 INFO: Ochyro startup [in /home/anonymous/sites/flask_mega/app/__init__.py:30
2019-11-03 10:46:57,533 INFO: Ochyro startup [in /home/anonymous/sites/flask_mega/app/__init__.py:30
2019-11-03 10:48:28,041 INFO: Ochyro startup [in /home/anonymous/sites/flask_mega/app/__init__.py:30
2019-11-03 11:11:34,288 INFO: Ochyro startup [in /home/anonymous/sites/flask_mega/app/__init__.py:30
2019-11-03 11:44:57,056 INFO: Ochyro startup [in /home/anonymous/sites/flask_mega/app/__init__.py:30
2019-11-03 11:45:22,037 INFO: Ochyro startup [in /home/anonymous/sites/flask_mega/app/__init__.py:30
2019-11-03 11:45:47,201 INFO: Ochyro startup [in /home/anonymous/sites/flask_mega/app/__init__.py:30
2019-11-03 11:46:58,311 INFO: Ochyro startup [in /home/anonymous/sites/flask_mega/app/__init__.py:30
2019-11-03 12:47:41,094 INFO: Ochyro startup [in /home/anonymous/sites/flask_mega/app/__init__.py:30
2019-11-03 17:03:10,119 ERROR: Exception on /register [POST] [in /home/anonymous/sites/flask_mega/env/lib/python3.7/site-packages/flask/app.py:1891
Traceback (most recent call last):
  File "/home/anonymous/sites/flask_mega/env/lib/python3.7/site-packages/sqlalchemy/engine/base.py", line 1249, in _execute_context
    cursor, statement, parameters, context
  File "/home/anonymous/sites/flask_mega/env/lib/python3.7/site-packages/sqlalchemy/engine/default.py", line 580, in do_execute
    cursor.execute(statement, parameters)
sqlite3.OperationalError: database is locked

The above exception was the direct cause of the following exception:

Traceback (most recent call last):
  File "/home/anonymous/sites/flask_mega/env/lib/python3.7/site-packages/flask/app.py", line 2446, in wsgi_app
    response = self.full_dispatch_request()
  File "/home/anonymous/sites/flask_mega/env/lib/python3.7/site-packages/flask/app.py", line 1951, in full_dispatch_request
    rv = self.handle_user_exception(e)
  File "/home/anonymous/sites/flask_mega/env/lib/python3.7/site-packages/flask/app.py", line 1820, in handle_user_exception
    reraise(exc_type, exc_value, tb)
  File "/home/anonymous/sites/flask_mega/env/lib/python3.7/site-packages/flask/_compat.py", line 39, in reraise
    raise value
  File "/home/anonymous/sites/flask_mega/env/lib/python3.7/site-packages/flask/app.py", line 1949, in full_dispatch_request
    rv = self.dispatch_request()
  File "/home/anonymous/sites/flask_mega/env/lib/python3.7/site-packages/flask/app.py", line 1935, in dispatch_request
    return self.view_functions[rule.endpoint](**req.view_args)
  File "/home/anonymous/sites/flask_mega/app/routes.py", line 76, in register
    db.session.commit()
  File "/home/anonymous/sites/flask_mega/env/lib/python3.7/site-packages/sqlalchemy/orm/scoping.py", line 162, in do
    return getattr(self.registry(), name)(*args, **kwargs)
  File "/home/anonymous/sites/flask_mega/env/lib/python3.7/site-packages/sqlalchemy/orm/session.py", line 1027, in commit
    self.transaction.commit()
  File "/home/anonymous/sites/flask_mega/env/lib/python3.7/site-packages/sqlalchemy/orm/session.py", line 494, in commit
    self._prepare_impl()
  File "/home/anonymous/sites/flask_mega/env/lib/python3.7/site-packages/sqlalchemy/orm/session.py", line 473, in _prepare_impl
    self.session.flush()
  File "/home/anonymous/sites/flask_mega/env/lib/python3.7/site-packages/sqlalchemy/orm/session.py", line 2470, in flush
    self._flush(objects)
  File "/home/anonymous/sites/flask_mega/env/lib/python3.7/site-packages/sqlalchemy/orm/session.py", line 2608, in _flush
    transaction.rollback(_capture_exception=True)
  File "/home/anonymous/sites/flask_mega/env/lib/python3.7/site-packages/sqlalchemy/util/langhelpers.py", line 68, in __exit__
    compat.reraise(exc_type, exc_value, exc_tb)
  File "/home/anonymous/sites/flask_mega/env/lib/python3.7/site-packages/sqlalchemy/util/compat.py", line 153, in reraise
    raise value
  File "/home/anonymous/sites/flask_mega/env/lib/python3.7/site-packages/sqlalchemy/orm/session.py", line 2568, in _flush
    flush_context.execute()
  File "/home/anonymous/sites/flask_mega/env/lib/python3.7/site-packages/sqlalchemy/orm/unitofwork.py", line 422, in execute
    rec.execute(self)
  File "/home/anonymous/sites/flask_mega/env/lib/python3.7/site-packages/sqlalchemy/orm/unitofwork.py", line 589, in execute
    uow,
  File "/home/anonymous/sites/flask_mega/env/lib/python3.7/site-packages/sqlalchemy/orm/persistence.py", line 245, in save_obj
    insert,
  File "/home/anonymous/sites/flask_mega/env/lib/python3.7/site-packages/sqlalchemy/orm/persistence.py", line 1137, in _emit_insert_statements
    statement, params
  File "/home/anonymous/sites/flask_mega/env/lib/python3.7/site-packages/sqlalchemy/engine/base.py", line 988, in execute
    return meth(self, multiparams, params)
  File "/home/anonymous/sites/flask_mega/env/lib/python3.7/site-packages/sqlalchemy/sql/elements.py", line 287, in _execute_on_connection
    return connection._execute_clauseelement(self, multiparams, params)
  File "/home/anonymous/sites/flask_mega/env/lib/python3.7/site-packages/sqlalchemy/engine/base.py", line 1107, in _execute_clauseelement
    distilled_params,
  File "/home/anonymous/sites/flask_mega/env/lib/python3.7/site-packages/sqlalchemy/engine/base.py", line 1253, in _execute_context
    e, statement, parameters, cursor, context
  File "/home/anonymous/sites/flask_mega/env/lib/python3.7/site-packages/sqlalchemy/engine/base.py", line 1473, in _handle_dbapi_exception
    util.raise_from_cause(sqlalchemy_exception, exc_info)
  File "/home/anonymous/sites/flask_mega/env/lib/python3.7/site-packages/sqlalchemy/util/compat.py", line 398, in raise_from_cause
    reraise(type(exception), exception, tb=exc_tb, cause=cause)
  File "/home/anonymous/sites/flask_mega/env/lib/python3.7/site-packages/sqlalchemy/util/compat.py", line 152, in reraise
    raise value.with_traceback(tb)
  File "/home/anonymous/sites/flask_mega/env/lib/python3.7/site-packages/sqlalchemy/engine/base.py", line 1249, in _execute_context
    cursor, statement, parameters, context
  File "/home/anonymous/sites/flask_mega/env/lib/python3.7/site-packages/sqlalchemy/engine/default.py", line 580, in do_execute
    cursor.execute(statement, parameters)
sqlalchemy.exc.OperationalError: (sqlite3.OperationalError) database is locked
[SQL: INSERT INTO user (username, email, password_hash, last_login, roles) VALUES (?, ?, ?, ?, ?)]
[parameters: ('bob', 'bob@dog.com', 'pbkdf2:sha256:150000$o8jqQ2SS$282d646627ae035e998b44f9e5c4ce9f94f6c4c5a549867dcbfa9b399b5a8802', '2019-11-03 22:03:05.106866', None)]
(Background on this error at: http://sqlalche.me/e/e3q8)
